Workbook

Sheet README
B2: Dashboards for Customer Churn Analysis
B3: E-Commerce Customer Churn — Simulated Dataset & Dashboard Workbook
B5: How this workbook is organised
B6: 1. Raw Data — the simulated source dataset (5,630-row Kaggle schema, scaled to 1,500 customers), imported as-is including missing values. Do not edit this sheet — it represents the raw data extract.
B7: 2. Lookup Tables — reference tables used by lookup formulas in Cleaned Data (City Tier labels, Satisfaction labels, Risk thresholds).
B8: 3. Cleaned Data — formula-driven copy of Raw Data: missing values are imputed with INDEX/MATCH + AVERAGE/median formulas, plus derived columns (Tenure Bucket, Risk Segment, City Tier Label) built with lookup and nested IF formulas.
B9: 4. Summary Calculations — COUNTIFS / AVERAGEIFS / SUMIFS pivot-style breakdowns of churn by segment, feeding the Dashboard charts.
B10: 5. Dashboard — KPI cards and charts for presentation. All numbers are live formulas — change Raw Data and everything recalculates.
B12: Editing this workbook
B13: Cells shaded yellow are the editable/raw input area (Raw Data sheet). Every other sheet is formula-driven — edit Raw Data and the rest of the workbook updates automatically.
B14: This dataset is a SIMULATED dataset built to match the structure of the public Kaggle dataset 'Ecommerce Customer Churn Analysis and Prediction' (ankitverma2010), created for this capstone per the assignment brief.

Sheet Raw Data
A1: CustomerID | B1: Churn | C1: Tenure | D1: PreferredLoginDevice | E1: CityTier | F1: WarehouseToHome | G1: PreferredPaymentMode | H1: Gender | I1: HourSpendOnApp | J1: NumberOfDeviceRegistered | K1: PreferedOrderCat | L1: SatisfactionScore | M1: MaritalStatus | N1: NumberOfAddress | O1: Complain | P1: OrderAmountHikeFromlastYear | Q1: CouponUsed | R1: OrderCount | S1: DaySinceLastOrder | T1: CashbackAmount
A2: 50001 | B2: 0 | C2: 11 | D2: Computer | E2: 1 | F2: 17 | G2: UPI | H2: Male | I2: 3.6 | J2: 5 | K2: Others | L2: 3 | M2: Married | N2: 15 | O2: 0 | P2: 17 | Q2: 2 | R2: 2 | S2: 3 | T2: 198.83
A3: 50002 | B3: 0 | C3: 25 | D3: Mobile Phone | E3: 1 | F3: 5 | G3: Credit Card | H3: Female | I3: 3.5 | J3: 3 | K3: Mobile Phone | L3: 1 | M3: Married | N3: 1 | O3: 0 | P3: 15.4 | Q3: 1 | R3: 5 | S3: 4 | T3: 133.09
A4: 50003 | B4: 0 | C4: 12 | D4: Mobile Phone | E4: 3 | F4: 17 | G4: Debit Card | H4: Female | I4: 2.5 | J4: 4 | K4: Mobile Phone | L4: 1 | M4: Married | N4: 1 | O4: 0 | P4: 13.3 | Q4: 2 | R4: 2 | S4: 1 | T4: 191.3
A5: 50004 | B5: 0 | C5: 1 | D5: Mobile Phone | E5: 2 | F5: 13 | G5: UPI | H5: Male | I5: 2.4 | J5: 4 | K5: Fashion | L5: 5 | M5: Single | N5: 1 | O5: 0 | P5: 14.6 | R5: 3 | S5: 15 | T5: 223.6
A6: 50005 | B6: 0 | C6: 8 | D6: Phone | E6: 2 | F6: 5 | G6: Cash on Delivery | H6: Male | I6: 2 | J6: 3 | K6: Laptop & Accessory | L6: 5 | M6: Married | N6: 4 | O6: 1 | P6: 14.2 | Q6: 2 | R6: 3 | S6: 3 | T6: 147.76
A7: 50006 | B7: 0 | C7: 9 | D7: Mobile Phone | E7: 1 | F7: 8 | G7: Cash on Delivery | H7: Male | I7: 3 | J7: 1 | K7: Laptop & Accessory | L7: 4 | M7: Married | N7: 1 | O7: 0 | Q7: 1 | R7: 5 | S7: 1 | T7: 186.54
A8: 50007 | B8: 0 | C8: 5 | D8: Mobile Phone | E8: 3 | F8: 11 | G8: Credit Card | H8: Female | I8: 2.1 | J8: 4 | K8: Fashion | L8: 3 | M8: Divorced | N8: 4 | O8: 0 | P8: 17.2 | Q8: 7 | R8: 3 | S8: 0 | T8: 172
A9: 50008 | B9: 0 | C9: 13 | D9: Mobile Phone | E9: 1 | F9: 30 | G9: Debit Card | H9: Female | I9: 2.1 | J9: 3 | K9: Mobile Phone | L9: 5 | M9: Married | N9: 1 | O9: 0 | P9: 18.4 | Q9: 2 | R9: 3 | S9: 3 | T9: 271.43
A10: 50009 | B10: 1 | C10: 27 | D10: Computer | E10: 1 | F10: 19 | G10: Credit Card | H10: Male | I10: 2.6 | J10: 4 | K10: Grocery | L10: 4 | M10: Divorced | N10: 3 | O10: 0 | P10: 11.9 | Q10: 0 | R10: 4 | S10: 2 | T10: 226.84
A11: 50010 | B11: 0 | C11: 25 | D11: Mobile Phone | E11: 2 | F11: 5 | G11: Debit Card | H11: Male | I11: 2.6 | J11: 3 | K11: Others | L11: 5 | M11: Married | N11: 5 | O11: 1 | P11: 21 | Q11: 1 | R11: 3 | S11: 1 | T11: 213.5
A12: 50011 | B12: 0 | C12: 5 | D12: Phone | E12: 1 | F12: 18 | G12: Cash on Delivery | H12: Male | I12: 2.5 | J12: 3 | K12: Mobile Phone | L12: 4 | M12: Married | N12: 2 | O12: 1 | P12: 14.5 | Q12: 3 | R12: 2 | S12: 0 | T12: 85.58
A13: 50012 | B13: 0 | C13: 1 | D13: Mobile Phone | E13: 1 | F13: 5 | G13: Debit Card | H13: Male | I13: 3.2 | J13: 5 | K13: Mobile Phone | L13: 3 | M13: Single | N13: 2 | O13: 0 | P13: 12.1 | Q13: 2 | R13: 4 | S13: 4 | T13: 189.51
A14: 50013 | B14: 0 | C14: 41 | D14: Phone | E14: 2 | F14: 23 | G14: Debit Card | H14: Female | I14: 3 | J14: 2 | K14: Mobile Phone | L14: 3 | M14: Divorced | N14: 1 | O14: 0 | P14: 14.5 | Q14: 2 | R14: 3 | S14: 4 | T14: 171.47
A15: 50014 | B15: 0 | C15: 18 | D15: Mobile Phone | E15: 3 | F15: 11 | G15: Credit Card | H15: Male | I15: 2.7 | J15: 4 | K15: Others | L15: 2 | M15: Married | N15: 1 | O15: 0 | P15: 24.7 | Q15: 1 | R15: 3 | S15: 0 | T15: 171
A16: 50015 | B16: 0 | C16: 1 | D16: Computer | E16: 1 | F16: 14 | G16: Credit Card | H16: Male | I16: 3 | J16: 3 | K16: Grocery | L16: 3 | M16: Divorced | N16: 2 | O16: 0 | P16: 14.6 | Q16: 0 | R16: 3 | S16: 4 | T16: 94.01
A17: 50016 | B17: 0 | C17: 25 | D17: Phone | E17: 3 | F17: 25 | G17: UPI | H17: Female | J17: 3 | K17: Others | L17: 4 | M17: Married | N17: 2 | O17: 0 | P17: 14.9 | Q17: 3 | R17: 6 | S17: 15 | T17: 120.17
A18: 50017 | B18: 0 | C18: 20 | D18: Mobile Phone | E18: 3 | F18: 5 | G18: Credit Card | H18: Female | I18: 3 | J18: 3 | K18: Laptop & Accessory | L18: 5 | M18: Married | N18: 8 | O18: 0 | P18: 15.3 | Q18: 3 | R18: 3 | S18: 19 | T18: 176.26
A19: 50018 | B19: 0 | C19: 7 | D19: Phone | E19: 1 | F19: 5 | G19: Debit Card | H19: Male | I19: 3 | J19: 2 | K19: Fashion | L19: 4 | M19: Single | N19: 8 | O19: 0 | P19: 15.5 | R19: 3 | S19: 10 | T19: 241.29
A20: 50019 | B20: 0 | C20: 8 | D20: Mobile Phone | E20: 1 | F20: 10 | G20: Debit Card | H20: Female | I20: 1.8 | J20: 4 | K20: Laptop & Accessory | L20: 3 | M20: Single | N20: 6 | O20: 0 | P20: 13.3 | Q20: 0 | R20: 4 | S20: 8 | T20: 147.52
A21: 50020 | B21: 0 | C21: 5 | D21: Phone | E21: 1 | F21: 23 | G21: Credit Card | H21: Male | I21: 3.6 | J21: 5 | K21: Laptop & Accessory | L21: 1 | M21: Divorced | N21: 1 | O21: 1 | Q21: 2 | R21: 4 | S21: 1 | T21: 158
A22: 50021 | B22: 0 | C22: 0 | D22: Computer | E22: 1 | F22: 5 | G22: Debit Card | H22: Female | I22: 2.3 | J22: 4 | K22: Others | L22: 1 | M22: Single | N22: 4 | O22: 1 | P22: 19.8 | Q22: 3 | R22: 5 | S22: 0 | T22: 277.96
A23: 50022 | B23: 0 | C23: 4 | D23: Mobile Phone | E23: 1 | F23: 5 | G23: E wallet | H23: Female | I23: 3 | J23: 3 | K23: Laptop & Accessory | L23: 3 | M23: Single | N23: 1 | O23: 1 | P23: 17.1 | Q23: 1 | R23: 4 | S23: 2 | T23: 163.67
A24: 50023 | B24: 0 | C24: 16 | D24: Mobile Phone | E24: 3 | F24: 11 | G24: Credit Card | H24: Male | I24: 3.7 | J24: 2 | K24: Others | L24: 3 | M24: Married | N24: 1 | O24: 0 | P24: 12.1 | Q24: 3 | R24: 5 | S24: 4 | T24: 172.92
A25: 50024 | B25: 0 | C25: 0 | D25: Mobile Phone | E25: 3 | F25: 19 | G25: E wallet | H25: Female | I25: 3.5 | J25: 4 | K25: Laptop & Accessory | L25: 4 | M25: Married | N25: 1 | O25: 0 | P25: 14.8 | Q25: 4 | R25: 4 | S25: 9 | T25: 173.66
A26: 50025 | B26: 0 | C26: 4 | D26: Mobile Phone | E26: 2 | F26: 24 | G26: Cash on Delivery | H26: Female | I26: 2.9 | J26: 5 | K26: Grocery | L26: 1 | M26: Single | N26: 1 | O26: 0 | P26: 14.1 | Q26: 3 | R26: 2 | S26: 1 | T26: 106
A27: 50026 | B27: 0 | C27: 5 | D27: Mobile Phone | E27: 1 | F27: 11 | G27: Cash on Delivery | H27: Male | I27: 2.6 | J27: 3 | K27: Laptop & Accessory | L27: 5 | M27: Single | N27: 1 | O27: 0 | P27: 16.2 | Q27: 4 | R27: 4 | S27: 3 | T27: 211.45
A28: 50027 | B28: 0 | C28: 7 | D28: Mobile Phone | E28: 3 | F28: 11 | G28: Cash on Delivery | H28: Male | I28: 3.6 | J28: 3 | K28: Mobile Phone | L28: 3 | M28: Married | N28: 2 | O28: 0 | P28: 20.7 | Q28: 2 | R28: 4 | S28: 5 | T28: 144.09
A29: 50028 | B29: 0 | C29: 25 | D29: Mobile Phone | E29: 3 | F29: 24 | G29: Debit Card | H29: Female | I29: 3.4 | J29: 3 | K29: Laptop & Accessory | L29: 5 | M29: Single | N29: 10 | O29: 0 | P29: 15.5 | Q29: 2 | R29: 2 | S29: 2 | T29: 178.35
A30: 50029 | B30: 0 | C30: 4 | D30: Computer | E30: 3 | F30: 5 | G30: Debit Card | H30: Male | I30: 2.5 | J30: 3 | K30: Mobile Phone | L30: 3 | M30: Married | N30: 1 | O30: 0 | P30: 15.7 | Q30: 2 | R30: 4 | S30: 3 | T30: 204.44
A31: 50030 | B31: 0 | C31: 4 | D31: Mobile Phone | E31: 1 | F31: 11 | G31: Debit Card | H31: Male | I31: 2.3 | J31: 1 | K31: Mobile Phone | L31: 2 | M31: Single | N31: 8 | O31: 0 | P31: 22.2 | Q31: 1 | R31: 3 | S31: 1 | T31: 286.84
A32: 50031 | B32: 1 | C32: 13 | D32: Mobile Phone | E32: 2 | F32: 16 | G32: UPI | H32: Female | I32: 1.4 | J32: 4 | K32: Fashion | L32: 4 | M32: Married | N32: 1 | O32: 0 | P32: 19.1 | Q32: 1 | R32: 1 | S32: 21 | T32: 107.52
A33: 50032 | B33: 0 | C33: 6 | D33: Computer | E33: 1 | F33: 18 | G33: Cash on Delivery | H33: Female | I33: 3 | J33: 2 | K33: Laptop & Accessory | L33: 4 | M33: Married | N33: 1 | O33: 0 | P33: 18 | Q33: 5 | R33: 1 | T33: 227.57
A34: 50033 | B34: 0 | C34: 2 | D34: Mobile Phone | E34: 1 | F34: 10 | G34: UPI | H34: Male | I34: 2.8 | J34: 2 | K34: Laptop & Accessory | L34: 3 | M34: Married | N34: 2 | O34: 0 | P34: 22.9 | Q34: 0 | R34: 3 | S34: 3 | T34: 227.78
A35: 50034 | B35: 0 | C35: 6 | D35: Mobile Phone | E35: 1 | F35: 15 | G35: Debit Card | H35: Male | J35: 4 | K35: Laptop & Accessory | L35: 3 | M35: Single | N35: 3 | O35: 0 | P35: 17.7 | Q35: 2 | R35: 5 | S35: 1 | T35: 144.9
A36: 50035 | B36: 0 | C36: 1 | D36: Mobile Phone | E36: 2 | F36: 5 | G36: Cash on Delivery | H36: Male | I36: 3.2 | J36: 2 | K36: Mobile Phone | L36: 1 | M36: Married | N36: 1 | O36: 1 | P36: 11 | Q36: 2 | R36: 3 | S36: 3 | T36: 212.97
A37: 50036 | B37: 0 | C37: 1 | D37: Phone | E37: 2 | F37: 9 | G37: Credit Card | H37: Male | I37: 3.8 | J37: 3 | K37: Grocery | L37: 4 | M37: Married | N37: 1 | O37: 0 | P37: 18.9 | Q37: 3 | R37: 5 | S37: 1 | T37: 270.39
A38: 50037 | B38: 0 | C38: 6 | D38: Phone | E38: 1 | F38: 18 | G38: Debit Card | H38: Male | I38: 2.4 | J38: 5 | K38: Grocery | L38: 5 | M38: Single | N38: 2 | O38: 1 | P38: 11 | Q38: 1 | R38: 2 | S38: 1 | T38: 137.93
A39: 50038 | B39: 0 | C39: 5 | D39: Mobile Phone | E39: 1 | F39: 7 | G39: Credit Card | H39: Female | I39: 3.7 | J39: 2 | K39: Laptop & Accessory | L39: 1 | M39: Married | N39: 1 | O39: 0 | P39: 17.6 | Q39: 1 | R39: 4 | S39: 1 | T39: 193.28
A40: 50039 | B40: 0 | C40: 24 | D40: Computer | E40: 1 | F40: 15 | G40: Debit Card | H40: Male | I40: 2.5 | J40: 2 | K40: Mobile Phone | L40: 3 | M40: Married | N40: 4 | O40: 0 | P40: 11 | Q40: 3 | R40: 4 | S40: 0 | T40: 202.26
...

Sheet Lookup Tables
B2: Lookup Tables
B3: Reference tables used by lookup formulas in the Cleaned Data sheet
B5: City Tier Lookup
B6: CityTier | C6: CityTierLabel
B7: 1 | C7: Tier 1 (Metro)
B8: 2 | C8: Tier 2 (Urban)
B9: 3 | C9: Tier 3 (Semi-urban/Rural)
B12: Satisfaction Score Lookup
B13: SatisfactionScore | C13: SatisfactionLabel
B14: 1 | C14: Very Low
B15: 2 | C15: Low
B16: 3 | C16: Neutral
B17: 4 | C17: High
B18: 5 | C18: Very High
B21: Tenure Bucket Rule (used in Cleaned Data nested IF formula)
B22: Bucket | C22: Rule
B23: 0-6 months | C23: Tenure <= 6
B24: 7-12 months | C24: 6 < Tenure <= 12
B25: 13-24 months | C25: 12 < Tenure <= 24
B26: 25+ months | C26: Tenure > 24
B29: Risk Segment Rule (used in Cleaned Data nested IF formula)
B30: Segment | C30: Rule
B31: High Risk | C31: Complain = 1 AND SatisfactionScore <= 2
B32: Medium Risk | C32: SatisfactionScore = 3 OR DaySinceLastOrder > 15
B33: Low Risk | C33: All other customers

Sheet Cleaned Data
A1: CustomerID | B1: Churn | C1: Tenure | D1: PreferredLoginDevice | E1: CityTier | F1: WarehouseToHome | G1: PreferredPaymentMode | H1: Gender | I1: HourSpendOnApp | J1: NumberOfDeviceRegistered | K1: PreferedOrderCat | L1: SatisfactionScore | M1: MaritalStatus | N1: NumberOfAddress | O1: Complain | P1: OrderAmountHikeFromlastYear | Q1: CouponUsed | R1: OrderCount | S1: DaySinceLastOrder | T1: CashbackAmount | U1: CityTierLabel | V1: TenureBucket | W1: RiskSegment | X1: ChurnLabel
A2: ='Raw Data'!A2 -> 50001 | B2: ='Raw Data'!B2 -> 0 | C2: ='Raw Data'!C2 -> 11 | D2: ='Raw Data'!D2 -> Computer | E2: ='Raw Data'!E2 -> 1 | F2: =IF('Raw Data'!F2="",ROUND(AVERAGE('Raw Data'!$F$2:$F$1501),1),'Raw Data'!F2) -> 17 | G2: ='Raw Data'!G2 -> UPI | H2: ='Raw Data'!H2 -> Male | I2: =IF('Raw Data'!I2="",ROUND(AVERAGE('Raw Data'!$I$2:$I$1501),1),'Raw Data'!I2) -> 3.6 | J2: ='Raw Data'!J2 -> 5 | K2: ='Raw Data'!K2 -> Others | L2: ='Raw Data'!L2 -> 3 | M2: ='Raw Data'!M2 -> Married | N2: ='Raw Data'!N2 -> 15 | O2: ='Raw Data'!O2 -> 0 | P2: =IF('Raw Data'!P2="",ROUND(AVERAGE('Raw Data'!$P$2:$P$1501),1),'Raw Data'!P2) -> 17 | Q2: =IF('Raw Data'!Q2="",ROUND(AVERAGE('Raw Data'!$Q$2:$Q$1501),0),'Raw Data'!Q2) -> 2 | R2: ='Raw Data'!R2 -> 2 | S2: =IF('Raw Data'!S2="",ROUND(AVERAGE('Raw Data'!$S$2:$S$1501),0),'Raw Data'!S2) -> 3 | T2: ='Raw Data'!T2 -> 198.83 | U2: =INDEX('Lookup Tables'!$C$7:$C$9,MATCH(E2,'Lookup Tables'!$B$7:$B$9,0)) -> Tier 1 (Metro) | V2: =IF(C2<=6,"0-6 months",IF(C2<=12,"7-12 months",IF(C2<=24,"13-24 months","25+ months"))) -> 7-12 months | W2: =IF(AND(O2=1,L2<=2),"High Risk",IF(OR(L2=3,S2>15),"Medium Risk","Low Risk")) -> Medium Risk | X2: =IF(B2=1,"Yes","No") -> No
A3: ='Raw Data'!A3 -> 50002 | B3: ='Raw Data'!B3 -> 0 | C3: ='Raw Data'!C3 -> 25 | D3: ='Raw Data'!D3 -> Mobile Phone | E3: ='Raw Data'!E3 -> 1 | F3: =IF('Raw Data'!F3="",ROUND(AVERAGE('Raw Data'!$F$2:$F$1501),1),'Raw Data'!F3) -> 5 | G3: ='Raw Data'!G3 -> Credit Card | H3: ='Raw Data'!H3 -> Female | I3: =IF('Raw Data'!I3="",ROUND(AVERAGE('Raw Data'!$I$2:$I$1501),1),'Raw Data'!I3) -> 3.5 | J3: ='Raw Data'!J3 -> 3 | K3: ='Raw Data'!K3 -> Mobile Phone | L3: ='Raw Data'!L3 -> 1 | M3: ='Raw Data'!M3 -> Married | N3: ='Raw Data'!N3 -> 1 | O3: ='Raw Data'!O3 -> 0 | P3: =IF('Raw Data'!P3="",ROUND(AVERAGE('Raw Data'!$P$2:$P$1501),1),'Raw Data'!P3) -> 15.4 | Q3: =IF('Raw Data'!Q3="",ROUND(AVERAGE('Raw Data'!$Q$2:$Q$1501),0),'Raw Data'!Q3) -> 1 | R3: ='Raw Data'!R3 -> 5 | S3: =IF('Raw Data'!S3="",ROUND(AVERAGE('Raw Data'!$S$2:$S$1501),0),'Raw Data'!S3) -> 4 | T3: ='Raw Data'!T3 -> 133.09 | U3: =INDEX('Lookup Tables'!$C$7:$C$9,MATCH(E3,'Lookup Tables'!$B$7:$B$9,0)) -> Tier 1 (Metro) | V3: =IF(C3<=6,"0-6 months",IF(C3<=12,"7-12 months",IF(C3<=24,"13-24 months","25+ months"))) -> 25+ months | W3: =IF(AND(O3=1,L3<=2),"High Risk",IF(OR(L3=3,S3>15),"Medium Risk","Low Risk")) -> Low Risk | X3: =IF(B3=1,"Yes","No") -> No
A4: ='Raw Data'!A4 -> 50003 | B4: ='Raw Data'!B4 -> 0 | C4: ='Raw Data'!C4 -> 12 | D4: ='Raw Data'!D4 -> Mobile Phone | E4: ='Raw Data'!E4 -> 3 | F4: =IF('Raw Data'!F4="",ROUND(AVERAGE('Raw Data'!$F$2:$F$1501),1),'Raw Data'!F4) -> 17 | G4: ='Raw Data'!G4 -> Debit Card | H4: ='Raw Data'!H4 -> Female | I4: =IF('Raw Data'!I4="",ROUND(AVERAGE('Raw Data'!$I$2:$I$1501),1),'Raw Data'!I4) -> 2.5 | J4: ='Raw Data'!J4 -> 4 | K4: ='Raw Data'!K4 -> Mobile Phone | L4: ='Raw Data'!L4 -> 1 | M4: ='Raw Data'!M4 -> Married | N4: ='Raw Data'!N4 -> 1 | O4: ='Raw Data'!O4 -> 0 | P4: =IF('Raw Data'!P4="",ROUND(AVERAGE('Raw Data'!$P$2:$P$1501),1),'Raw Data'!P4) -> 13.3 | Q4: =IF('Raw Data'!Q4="",ROUND(AVERAGE('Raw Data'!$Q$2:$Q$1501),0),'Raw Data'!Q4) -> 2 | R4: ='Raw Data'!R4 -> 2 | S4: =IF('Raw Data'!S4="",ROUND(AVERAGE('Raw Data'!$S$2:$S$1501),0),'Raw Data'!S4) -> 1 | T4: ='Raw Data'!T4 -> 191.3 | U4: =INDEX('Lookup Tables'!$C$7:$C$9,MATCH(E4,'Lookup Tables'!$B$7:$B$9,0)) -> Tier 3 (Semi-urban/Rural) | V4: =IF(C4<=6,"0-6 months",IF(C4<=12,"7-12 months",IF(C4<=24,"13-24 months","25+ months"))) -> 7-12 months | W4: =IF(AND(O4=1,L4<=2),"High Risk",IF(OR(L4=3,S4>15),"Medium Risk","Low Risk")) -> Low Risk | X4: =IF(B4=1,"Yes","No") -> No
A5: ='Raw Data'!A5 -> 50004 | B5: ='Raw Data'!B5 -> 0 | C5: ='Raw Data'!C5 -> 1 | D5: ='Raw Data'!D5 -> Mobile Phone | E5: ='Raw Data'!E5 -> 2 | F5: =IF('Raw Data'!F5="",ROUND(AVERAGE('Raw Data'!$F$2:$F$1501),1),'Raw Data'!F5) -> 13 | G5: ='Raw Data'!G5 -> UPI | H5: ='Raw Data'!H5 -> Male | I5: =IF('Raw Data'!I5="",ROUND(AVERAGE('Raw Data'!$I$2:$I$1501),1),'Raw Data'!I5) -> 2.4 | J5: ='Raw Data'!J5 -> 4 | K5: ='Raw Data'!K5 -> Fashion | L5: ='Raw Data'!L5 -> 5 | M5: ='Raw Data'!M5 -> Single | N5: ='Raw Data'!N5 -> 1 | O5: ='Raw Data'!O5 -> 0 | P5: =IF('Raw Data'!P5="",ROUND(AVERAGE('Raw Data'!$P$2:$P$1501),1),'Raw Data'!P5) -> 14.6 | Q5: =IF('Raw Data'!Q5="",ROUND(AVERAGE('Raw Data'!$Q$2:$Q$1501),0),'Raw Data'!Q5) -> 2 | R5: ='Raw Data'!R5 -> 3 | S5: =IF('Raw Data'!S5="",ROUND(AVERAGE('Raw Data'!$S$2:$S$1501),0),'Raw Data'!S5) -> 15 | T5: ='Raw Data'!T5 -> 223.6 | U5: =INDEX('Lookup Tables'!$C$7:$C$9,MATCH(E5,'Lookup Tables'!$B$7:$B$9,0)) -> Tier 2 (Urban) | V5: =IF(C5<=6,"0-6 months",IF(C5<=12,"7-12 months",IF(C5<=24,"13-24 months","25+ months"))) -> 0-6 months | W5: =IF(AND(O5=1,L5<=2),"High Risk",IF(OR(L5=3,S5>15),"Medium Risk","Low Risk")) -> Low Risk | X5: =IF(B5=1,"Yes","No") -> No
A6: ='Raw Data'!A6 -> 50005 | B6: ='Raw Data'!B6 -> 0 | C6: ='Raw Data'!C6 -> 8 | D6: ='Raw Data'!D6 -> Phone | E6: ='Raw Data'!E6 -> 2 | F6: =IF('Raw Data'!F6="",ROUND(AVERAGE('Raw Data'!$F$2:$F$1501),1),'Raw Data'!F6) -> 5 | G6: ='Raw Data'!G6 -> Cash on Delivery | H6: ='Raw Data'!H6 -> Male | I6: =IF('Raw Data'!I6="",ROUND(AVERAGE('Raw Data'!$I$2:$I$1501),1),'Raw Data'!I6) -> 2 | J6: ='Raw Data'!J6 -> 3 | K6: ='Raw Data'!K6 -> Laptop & Accessory | L6: ='Raw Data'!L6 -> 5 | M6: ='Raw Data'!M6 -> Married | N6: ='Raw Data'!N6 -> 4 | O6: ='Raw Data'!O6 -> 1 | P6: =IF('Raw Data'!P6="",ROUND(AVERAGE('Raw Data'!$P$2:$P$1501),1),'Raw Data'!P6) -> 14.2 | Q6: =IF('Raw Data'!Q6="",ROUND(AVERAGE('Raw Data'!$Q$2:$Q$1501),0),'Raw Data'!Q6) -> 2 | R6: ='Raw Data'!R6 -> 3 | S6: =IF('Raw Data'!S6="",ROUND(AVERAGE('Raw Data'!$S$2:$S$1501),0),'Raw Data'!S6) -> 3 | T6: ='Raw Data'!T6 -> 147.76 | U6: =INDEX('Lookup Tables'!$C$7:$C$9,MATCH(E6,'Lookup Tables'!$B$7:$B$9,0)) -> Tier 2 (Urban) | V6: =IF(C6<=6,"0-6 months",IF(C6<=12,"7-12 months",IF(C6<=24,"13-24 months","25+ months"))) -> 7-12 months | W6: =IF(AND(O6=1,L6<=2),"High Risk",IF(OR(L6=3,S6>15),"Medium Risk","Low Risk")) -> Low Risk | X6: =IF(B6=1,"Yes","No") -> No
A7: ='Raw Data'!A7 -> 50006 | B7: ='Raw Data'!B7 -> 0 | C7: ='Raw Data'!C7 -> 9 | D7: ='Raw Data'!D7 -> Mobile Phone | E7: ='Raw Data'!E7 -> 1 | F7: =IF('Raw Data'!F7="",ROUND(AVERAGE('Raw Data'!$F$2:$F$1501),1),'Raw Data'!F7) -> 8 | G7: ='Raw Data'!G7 -> Cash on Delivery | H7: ='Raw Data'!H7 -> Male | I7: =IF('Raw Data'!I7="",ROUND(AVERAGE('Raw Data'!$I$2:$I$1501),1),'Raw Data'!I7) -> 3 | J7: ='Raw Data'!J7 -> 1 | K7: ='Raw Data'!K7 -> Laptop & Accessory | L7: ='Raw Data'!L7 -> 4 | M7: ='Raw Data'!M7 -> Married | N7: ='Raw Data'!N7 -> 1 | O7: ='Raw Data'!O7 -> 0 | P7: =IF('Raw Data'!P7="",ROUND(AVERAGE('Raw Data'!$P$2:$P$1501),1),'Raw Data'!P7) -> 16.3 | Q7: =IF('Raw Data'!Q7="",ROUND(AVERAGE('Raw Data'!$Q$2:$Q$1501),0),'Raw Data'!Q7) -> 1 | R7: ='Raw Data'!R7 -> 5 | S7: =IF('Raw Data'!S7="",ROUND(AVERAGE('Raw Data'!$S$2:$S$1501),0),'Raw Data'!S7) -> 1 | T7: ='Raw Data'!T7 -> 186.54 | U7: =INDEX('Lookup Tables'!$C$7:$C$9,MATCH(E7,'Lookup Tables'!$B$7:$B$9,0)) -> Tier 1 (Metro) | V7: =IF(C7<=6,"0-6 months",IF(C7<=12,"7-12 months",IF(C7<=24,"13-24 months","25+ months"))) -> 7-12 months | W7: =IF(AND(O7=1,L7<=2),"High Risk",IF(OR(L7=3,S7>15),"Medium Risk","Low Risk")) -> Low Risk | X7: =IF(B7=1,"Yes","No") -> No
A8: ='Raw Data'!A8 -> 50007 | B8: ='Raw Data'!B8 -> 0 | C8: ='Raw Data'!C8 -> 5 | D8: ='Raw Data'!D8 -> Mobile Phone | E8: ='Raw Data'!E8 -> 3 | F8: =IF('Raw Data'!F8="",ROUND(AVERAGE('Raw Data'!$F$2:$F$1501),1),'Raw Data'!F8) -> 11 | G8: ='Raw Data'!G8 -> Credit Card | H8: ='Raw Data'!H8 -> Female | I8: =IF('Raw Data'!I8="",ROUND(AVERAGE('Raw Data'!$I$2:$I$1501),1),'Raw Data'!I8) -> 2.1 | J8: ='Raw Data'!J8 -> 4 | K8: ='Raw Data'!K8 -> Fashion | L8: ='Raw Data'!L8 -> 3 | M8: ='Raw Data'!M8 -> Divorced | N8: ='Raw Data'!N8 -> 4 | O8: ='Raw Data'!O8 -> 0 | P8: =IF('Raw Data'!P8="",ROUND(AVERAGE('Raw Data'!$P$2:$P$1501),1),'Raw Data'!P8) -> 17.2 | Q8: =IF('Raw Data'!Q8="",ROUND(AVERAGE('Raw Data'!$Q$2:$Q$1501),0),'Raw Data'!Q8) -> 7 | R8: ='Raw Data'!R8 -> 3 | S8: =IF('Raw Data'!S8="",ROUND(AVERAGE('Raw Data'!$S$2:$S$1501),0),'Raw Data'!S8) -> 0 | T8: ='Raw Data'!T8 -> 172 | U8: =INDEX('Lookup Tables'!$C$7:$C$9,MATCH(E8,'Lookup Tables'!$B$7:$B$9,0)) -> Tier 3 (Semi-urban/Rural) | V8: =IF(C8<=6,"0-6 months",IF(C8<=12,"7-12 months",IF(C8<=24,"13-24 months","25+ months"))) -> 0-6 months | W8: =IF(AND(O8=1,L8<=2),"High Risk",IF(OR(L8=3,S8>15),"Medium Risk","Low Risk")) -> Medium Risk | X8: =IF(B8=1,"Yes","No") -> No
A9: ='Raw Data'!A9 -> 50008 | B9: ='Raw Data'!B9 -> 0 | C9: ='Raw Data'!C9 -> 13 | D9: ='Raw Data'!D9 -> Mobile Phone | E9: ='Raw Data'!E9 -> 1 | F9: =IF('Raw Data'!F9="",ROUND(AVERAGE('Raw Data'!$F$2:$F$1501),1),'Raw Data'!F9) -> 30 | G9: ='Raw Data'!G9 -> Debit Card | H9: ='Raw Data'!H9 -> Female | I9: =IF('Raw Data'!I9="",ROUND(AVERAGE('Raw Data'!$I$2:$I$1501),1),'Raw Data'!I9) -> 2.1 | J9: ='Raw Data'!J9 -> 3 | K9: ='Raw Data'!K9 -> Mobile Phone | L9: ='Raw Data'!L9 -> 5 | M9: ='Raw Data'!M9 -> Married | N9: ='Raw Data'!N9 -> 1 | O9: ='Raw Data'!O9 -> 0 | P9: =IF('Raw Data'!P9="",ROUND(AVERAGE('Raw Data'!$P$2:$P$1501),1),'Raw Data'!P9) -> 18.4 | Q9: =IF('Raw Data'!Q9="",ROUND(AVERAGE('Raw Data'!$Q$2:$Q$1501),0),'Raw Data'!Q9) -> 2 | R9: ='Raw Data'!R9 -> 3 | S9: =IF('Raw Data'!S9="",ROUND(AVERAGE('Raw Data'!$S$2:$S$1501),0),'Raw Data'!S9) -> 3 | T9: ='Raw Data'!T9 -> 271.43 | U9: =INDEX('Lookup Tables'!$C$7:$C$9,MATCH(E9,'Lookup Tables'!$B$7:$B$9,0)) -> Tier 1 (Metro) | V9: =IF(C9<=6,"0-6 months",IF(C9<=12,"7-12 months",IF(C9<=24,"13-24 months","25+ months"))) -> 13-24 months | W9: =IF(AND(O9=1,L9<=2),"High Risk",IF(OR(L9=3,S9>15),"Medium Risk","Low Risk")) -> Low Risk | X9: =IF(B9=1,"Yes","No") -> No
A10: ='Raw Data'!A10 -> 50009 | B10: ='Raw Data'!B10 -> 1 | C10: ='Raw Data'!C10 -> 27 | D10: ='Raw Data'!D10 -> Computer | E10: ='Raw Data'!E10 -> 1 | F10: =IF('Raw Data'!F10="",ROUND(AVERAGE('Raw Data'!$F$2:$F$1501),1),'Raw Data'!F10) -> 19 | G10: ='Raw Data'!G10 -> Credit Card | H10: ='Raw Data'!H10 -> Male | I10: =IF('Raw Data'!I10="",ROUND(AVERAGE('Raw Data'!$I$2:$I$1501),1),'Raw Data'!I10) -> 2.6 | J10: ='Raw Data'!J10 -> 4 | K10: ='Raw Data'!K10 -> Grocery | L10: ='Raw Data'!L10 -> 4 | M10: ='Raw Data'!M10 -> Divorced | N10: ='Raw Data'!N10 -> 3 | O10: ='Raw Data'!O10 -> 0 | P10: =IF('Raw Data'!P10="",ROUND(AVERAGE('Raw Data'!$P$2:$P$1501),1),'Raw Data'!P10) -> 11.9 | Q10: =IF('Raw Data'!Q10="",ROUND(AVERAGE('Raw Data'!$Q$2:$Q$1501),0),'Raw Data'!Q10) -> 0 | R10: ='Raw Data'!R10 -> 4 | S10: =IF('Raw Data'!S10="",ROUND(AVERAGE('Raw Data'!$S$2:$S$1501),0),'Raw Data'!S10) -> 2 | T10: ='Raw Data'!T10 -> 226.84 | U10: =INDEX('Lookup Tables'!$C$7:$C$9,MATCH(E10,'Lookup Tables'!$B$7:$B$9,0)) -> Tier 1 (Metro) | V10: =IF(C10<=6,"0-6 months",IF(C10<=12,"7-12 months",IF(C10<=24,"13-24 months","25+ months"))) -> 25+ months | W10: =IF(AND(O10=1,L10<=2),"High Risk",IF(OR(L10=3,S10>15),"Medium Risk","Low Risk")) -> Low Risk | X10: =IF(B10=1,"Yes","No") -> Yes
A11: ='Raw Data'!A11 -> 50010 | B11: ='Raw Data'!B11 -> 0 | C11: ='Raw Data'!C11 -> 25 | D11: ='Raw Data'!D11 -> Mobile Phone | E11: ='Raw Data'!E11 -> 2 | F11: =IF('Raw Data'!F11="",ROUND(AVERAGE('Raw Data'!$F$2:$F$1501),1),'Raw Data'!F11) -> 5 | G11: ='Raw Data'!G11 -> Debit Card | H11: ='Raw Data'!H11 -> Male | I11: =IF('Raw Data'!I11="",ROUND(AVERAGE('Raw Data'!$I$2:$I$1501),1),'Raw Data'!I11) -> 2.6 | J11: ='Raw Data'!J11 -> 3 | K11: ='Raw Data'!K11 -> Others | L11: ='Raw Data'!L11 -> 5 | M11: ='Raw Data'!M11 -> Married | N11: ='Raw Data'!N11 -> 5 | O11: ='Raw Data'!O11 -> 1 | P11: =IF('Raw Data'!P11="",ROUND(AVERAGE('Raw Data'!$P$2:$P$1501),1),'Raw Data'!P11) -> 21 | Q11: =IF('Raw Data'!Q11="",ROUND(AVERAGE('Raw Data'!$Q$2:$Q$1501),0),'Raw Data'!Q11) -> 1 | R11: ='Raw Data'!R11 -> 3 | S11: =IF('Raw Data'!S11="",ROUND(AVERAGE('Raw Data'!$S$2:$S$1501),0),'Raw Data'!S11) -> 1 | T11: ='Raw Data'!T11 -> 213.5 | U11: =INDEX('Lookup Tables'!$C$7:$C$9,MATCH(E11,'Lookup Tables'!$B$7:$B$9,0)) -> Tier 2 (Urban) | V11: =IF(C11<=6,"0-6 months",IF(C11<=12,"7-12 months",IF(C11<=24,"13-24 months","25+ months"))) -> 25+ months | W11: =IF(AND(O11=1,L11<=2),"High Risk",IF(OR(L11=3,S11>15),"Medium Risk","Low Risk")) -> Low Risk | X11: =IF(B11=1,"Yes","No") -> No
A12: ='Raw Data'!A12 -> 50011 | B12: ='Raw Data'!B12 -> 0 | C12: ='Raw Data'!C12 -> 5 | D12: ='Raw Data'!D12 -> Phone | E12: ='Raw Data'!E12 -> 1 | F12: =IF('Raw Data'!F12="",ROUND(AVERAGE('Raw Data'!$F$2:$F$1501),1),'Raw Data'!F12) -> 18 | G12: ='Raw Data'!G12 -> Cash on Delivery | H12: ='Raw Data'!H12 -> Male | I12: =IF('Raw Data'!I12="",ROUND(AVERAGE('Raw Data'!$I$2:$I$1501),1),'Raw Data'!I12) -> 2.5 | J12: ='Raw Data'!J12 -> 3 | K12: ='Raw Data'!K12 -> Mobile Phone | L12: ='Raw Data'!L12 -> 4 | M12: ='Raw Data'!M12 -> Married | N12: ='Raw Data'!N12 -> 2 | O12: ='Raw Data'!O12 -> 1 | P12: =IF('Raw Data'!P12="",ROUND(AVERAGE('Raw Data'!$P$2:$P$1501),1),'Raw Data'!P12) -> 14.5 | Q12: =IF('Raw Data'!Q12="",ROUND(AVERAGE('Raw Data'!$Q$2:$Q$1501),0),'Raw Data'!Q12) -> 3 | R12: ='Raw Data'!R12 -> 2 | S12: =IF('Raw Data'!S12="",ROUND(AVERAGE('Raw Data'!$S$2:$S$1501),0),'Raw Data'!S12) -> 0 | T12: ='Raw Data'!T12 -> 85.58 | U12: =INDEX('Lookup Tables'!$C$7:$C$9,MATCH(E12,'Lookup Tables'!$B$7:$B$9,0)) -> Tier 1 (Metro) | V12: =IF(C12<=6,"0-6 months",IF(C12<=12,"7-12 months",IF(C12<=24,"13-24 months","25+ months"))) -> 0-6 months | W12: =IF(AND(O12=1,L12<=2),"High Risk",IF(OR(L12=3,S12>15),"Medium Risk","Low Risk")) -> Low Risk | X12: =IF(B12=1,"Yes","No") -> No
A13: ='Raw Data'!A13 -> 50012 | B13: ='Raw Data'!B13 -> 0 | C13: ='Raw Data'!C13 -> 1 | D13: ='Raw Data'!D13 -> Mobile Phone | E13: ='Raw Data'!E13 -> 1 | F13: =IF('Raw Data'!F13="",ROUND(AVERAGE('Raw Data'!$F$2:$F$1501),1),'Raw Data'!F13) -> 5 | G13: ='Raw Data'!G13 -> Debit Card | H13: ='Raw Data'!H13 -> Male | I13: =IF('Raw Data'!I13="",ROUND(AVERAGE('Raw Data'!$I$2:$I$1501),1),'Raw Data'!I13) -> 3.2 | J13: ='Raw Data'!J13 -> 5 | K13: ='Raw Data'!K13 -> Mobile Phone | L13: ='Raw Data'!L13 -> 3 | M13: ='Raw Data'!M13 -> Single | N13: ='Raw Data'!N13 -> 2 | O13: ='Raw Data'!O13 -> 0 | P13: =IF('Raw Data'!P13="",ROUND(AVERAGE('Raw Data'!$P$2:$P$1501),1),'Raw Data'!P13) -> 12.1 | Q13: =IF('Raw Data'!Q13="",ROUND(AVERAGE('Raw Data'!$Q$2:$Q$1501),0),'Raw Data'!Q13) -> 2 | R13: ='Raw Data'!R13 -> 4 | S13: =IF('Raw Data'!S13="",ROUND(AVERAGE('Raw Data'!$S$2:$S$1501),0),'Raw Data'!S13) -> 4 | T13: ='Raw Data'!T13 -> 189.51 | U13: =INDEX('Lookup Tables'!$C$7:$C$9,MATCH(E13,'Lookup Tables'!$B$7:$B$9,0)) -> Tier 1 (Metro) | V13: =IF(C13<=6,"0-6 months",IF(C13<=12,"7-12 months",IF(C13<=24,"13-24 months","25+ months"))) -> 0-6 months | W13: =IF(AND(O13=1,L13<=2),"High Risk",IF(OR(L13=3,S13>15),"Medium Risk","Low Risk")) -> Medium Risk | X13: =IF(B13=1,"Yes","No") -> No
... A1501: ='Raw Data'!A1501 -> 51500 | B1501: ='Raw Data'!B1501 -> 1 | C1501: ='Raw Data'!C1501 -> 0 | D1501: ='Raw Data'!D1501 -> Mobile Phone | E1501: ='Raw Data'!E1501 -> 1 | F1501: =IF('Raw Data'!F1501="",ROUND(AVERAGE('Raw Data'!$F$2:$F$1501),1),'Raw Data'!F1501) -> 28 | G1501: ='Raw Data'!G1501 -> Debit Card | H1501: ='Raw Data'!H1501 -> Female | I1501: =IF('Raw Data'!I1501="",ROUND(AVERAGE('Raw Data'!$I$2:$I$1501),1),'Raw Data'!I1501) -> 2.5 | J1501: ='Raw Data'!J1501 -> 4 | K1501: ='Raw Data'!K1501 -> Grocery | L1501: ='Raw Data'!L1501 -> 3 | M1501: ='Raw Data'!M1501 -> Divorced | N1501: ='Raw Data'!N1501 -> 7 | O1501: ='Raw Data'!O1501 -> 0 | P1501: =IF('Raw Data'!P1501="",ROUND(AVERAGE('Raw Data'!$P$2:$P$1501),1),'Raw Data'!P1501) -> 14.7 | Q1501: =IF('Raw Data'!Q1501="",ROUND(AVERAGE('Raw Data'!$Q$2:$Q$1501),0),'Raw Data'!Q1501) -> 2 | R1501: ='Raw Data'!R1501 -> 4 | S1501: =IF('Raw Data'!S1501="",ROUND(AVERAGE('Raw Data'!$S$2:$S$1501),0),'Raw Data'!S1501) -> 7 | T1501: ='Raw Data'!T1501 -> 225.27 | U1501: =INDEX('Lookup Tables'!$C$7:$C$9,MATCH(E1501,'Lookup Tables'!$B$7:$B$9,0)) -> Tier 1 (Metro) | V1501: =IF(C1501<=6,"0-6 months",IF(C1501<=12,"7-12 months",IF(C1501<=24,"13-24 months","25+ months"))) -> 0-6 months | W1501: =IF(AND(O1501=1,L1501<=2),"High Risk",IF(OR(L1501=3,S1501>15),"Medium Risk","Low Risk")) -> Medium Risk | X1501: =IF(B1501=1,"Yes","No") -> Yes

Sheet Summary Calculations
B2: Summary Calculations
B3: COUNTIFS / AVERAGEIFS breakdowns of churn by customer segment — feeds the Dashboard charts
B5: 1. Churn Rate by City Tier | G5: 2. Churn Rate by Preferred Order Category
B6: CityTierLabel | C6: Customers | D6: Churned | E6: Churn Rate | G6: PreferedOrderCat | H6: Customers | I6: Churned | J6: Churn Rate
B7: Tier 1 (Metro) | C7: =COUNTIFS('Cleaned Data'!$U$2:$U$1501,"Tier 1 (Metro)") -> 756 | D7: =COUNTIFS('Cleaned Data'!$U$2:$U$1501,"Tier 1 (Metro)",'Cleaned Data'!$B$2:$B$1501,1) -> 115 | E7: =IF(C7=0,0,D7/C7) -> 0.1521164 | G7: Laptop & Accessory | H7: =COUNTIFS('Cleaned Data'!$K$2:$K$1501,"Laptop & Accessory") -> 460 | I7: =COUNTIFS('Cleaned Data'!$K$2:$K$1501,"Laptop & Accessory",'Cleaned Data'!$B$2:$B$1501,1) -> 67 | J7: =IF(H7=0,0,I7/H7) -> 0.14565217
B8: Tier 2 (Urban) | C8: =COUNTIFS('Cleaned Data'!$U$2:$U$1501,"Tier 2 (Urban)") -> 298 | D8: =COUNTIFS('Cleaned Data'!$U$2:$U$1501,"Tier 2 (Urban)",'Cleaned Data'!$B$2:$B$1501,1) -> 38 | E8: =IF(C8=0,0,D8/C8) -> 0.12751678 | G8: Mobile Phone | H8: =COUNTIFS('Cleaned Data'!$K$2:$K$1501,"Mobile Phone") -> 442 | I8: =COUNTIFS('Cleaned Data'!$K$2:$K$1501,"Mobile Phone",'Cleaned Data'!$B$2:$B$1501,1) -> 72 | J8: =IF(H8=0,0,I8/H8) -> 0.16289593
B9: Tier 3 (Semi-urban/Rural) | C9: =COUNTIFS('Cleaned Data'!$U$2:$U$1501,"Tier 3 (Semi-urban/Rural)") -> 446 | D9: =COUNTIFS('Cleaned Data'!$U$2:$U$1501,"Tier 3 (Semi-urban/Rural)",'Cleaned Data'!$B$2:$B$1501,1) -> 62 | E9: =IF(C9=0,0,D9/C9) -> 0.13901345 | G9: Fashion | H9: =COUNTIFS('Cleaned Data'!$K$2:$K$1501,"Fashion") -> 265 | I9: =COUNTIFS('Cleaned Data'!$K$2:$K$1501,"Fashion",'Cleaned Data'!$B$2:$B$1501,1) -> 27 | J9: =IF(H9=0,0,I9/H9) -> 0.10188679
G10: Grocery | H10: =COUNTIFS('Cleaned Data'!$K$2:$K$1501,"Grocery") -> 195 | I10: =COUNTIFS('Cleaned Data'!$K$2:$K$1501,"Grocery",'Cleaned Data'!$B$2:$B$1501,1) -> 28 | J10: =IF(H10=0,0,I10/H10) -> 0.14358974
G11: Others | H11: =COUNTIFS('Cleaned Data'!$K$2:$K$1501,"Others") -> 138 | I11: =COUNTIFS('Cleaned Data'!$K$2:$K$1501,"Others",'Cleaned Data'!$B$2:$B$1501,1) -> 21 | J11: =IF(H11=0,0,I11/H11) -> 0.15217391
B13: 3. Churn Rate by Preferred Payment Mode | G13: 4. Churn Rate by Login Device
B14: PreferredPaymentMode | C14: Customers | D14: Churned | E14: Churn Rate | G14: PreferredLoginDevice | H14: Customers | I14: Churned | J14: Churn Rate
B15: Debit Card | C15: =COUNTIFS('Cleaned Data'!$G$2:$G$1501,"Debit Card") -> 550 | D15: =COUNTIFS('Cleaned Data'!$G$2:$G$1501,"Debit Card",'Cleaned Data'!$B$2:$B$1501,1) -> 79 | E15: =IF(C15=0,0,D15/C15) -> 0.14363636 | G15: Mobile Phone | H15: =COUNTIFS('Cleaned Data'!$D$2:$D$1501,"Mobile Phone") -> 849 | I15: =COUNTIFS('Cleaned Data'!$D$2:$D$1501,"Mobile Phone",'Cleaned Data'!$B$2:$B$1501,1) -> 113 | J15: =IF(H15=0,0,I15/H15) -> 0.13309776
B16: Credit Card | C16: =COUNTIFS('Cleaned Data'!$G$2:$G$1501,"Credit Card") -> 397 | D16: =COUNTIFS('Cleaned Data'!$G$2:$G$1501,"Credit Card",'Cleaned Data'!$B$2:$B$1501,1) -> 58 | E16: =IF(C16=0,0,D16/C16) -> 0.14609572 | G16: Computer | H16: =COUNTIFS('Cleaned Data'!$D$2:$D$1501,"Computer") -> 342 | I16: =COUNTIFS('Cleaned Data'!$D$2:$D$1501,"Computer",'Cleaned Data'!$B$2:$B$1501,1) -> 57 | J16: =IF(H16=0,0,I16/H16) -> 0.16666667
B17: E wallet | C17: =COUNTIFS('Cleaned Data'!$G$2:$G$1501,"E wallet") -> 222 | D17: =COUNTIFS('Cleaned Data'!$G$2:$G$1501,"E wallet",'Cleaned Data'!$B$2:$B$1501,1) -> 34 | E17: =IF(C17=0,0,D17/C17) -> 0.15315315 | G17: Phone | H17: =COUNTIFS('Cleaned Data'!$D$2:$D$1501,"Phone") -> 309 | I17: =COUNTIFS('Cleaned Data'!$D$2:$D$1501,"Phone",'Cleaned Data'!$B$2:$B$1501,1) -> 45 | J17: =IF(H17=0,0,I17/H17) -> 0.14563107
B18: UPI | C18: =COUNTIFS('Cleaned Data'!$G$2:$G$1501,"UPI") -> 196 | D18: =COUNTIFS('Cleaned Data'!$G$2:$G$1501,"UPI",'Cleaned Data'!$B$2:$B$1501,1) -> 24 | E18: =IF(C18=0,0,D18/C18) -> 0.12244898
B19: Cash on Delivery | C19: =COUNTIFS('Cleaned Data'!$G$2:$G$1501,"Cash on Delivery") -> 135 | D19: =COUNTIFS('Cleaned Data'!$G$2:$G$1501,"Cash on Delivery",'Cleaned Data'!$B$2:$B$1501,1) -> 20 | E19: =IF(C19=0,0,D19/C19) -> 0.14814815
B21: 5. Churn Rate by Marital Status | G21: 6. Churn Rate by Satisfaction Score
B22: MaritalStatus | C22: Customers | D22: Churned | E22: Churn Rate | G22: SatisfactionScore | H22: Customers | I22: Churned | J22: Churn Rate
B23: Single | C23: =COUNTIFS('Cleaned Data'!$M$2:$M$1501,"Single") -> 565 | D23: =COUNTIFS('Cleaned Data'!$M$2:$M$1501,"Single",'Cleaned Data'!$B$2:$B$1501,1) -> 78 | E23: =IF(C23=0,0,D23/C23) -> 0.1380531 | G23: 1 | H23: =COUNTIFS('Cleaned Data'!$L$2:$L$1501,1) -> 166 | I23: =COUNTIFS('Cleaned Data'!$L$2:$L$1501,1,'Cleaned Data'!$B$2:$B$1501,1) -> 27 | J23: =IF(H23=0,0,I23/H23) -> 0.1626506
B24: Married | C24: =COUNTIFS('Cleaned Data'!$M$2:$M$1501,"Married") -> 763 | D24: =COUNTIFS('Cleaned Data'!$M$2:$M$1501,"Married",'Cleaned Data'!$B$2:$B$1501,1) -> 112 | E24: =IF(C24=0,0,D24/C24) -> 0.14678899 | G24: 2 | H24: =COUNTIFS('Cleaned Data'!$L$2:$L$1501,2) -> 196 | I24: =COUNTIFS('Cleaned Data'!$L$2:$L$1501,2,'Cleaned Data'!$B$2:$B$1501,1) -> 39 | J24: =IF(H24=0,0,I24/H24) -> 0.19897959
B25: Divorced | C25: =COUNTIFS('Cleaned Data'!$M$2:$M$1501,"Divorced") -> 172 | D25: =COUNTIFS('Cleaned Data'!$M$2:$M$1501,"Divorced",'Cleaned Data'!$B$2:$B$1501,1) -> 25 | E25: =IF(C25=0,0,D25/C25) -> 0.14534884 | G25: 3 | H25: =COUNTIFS('Cleaned Data'!$L$2:$L$1501,3) -> 457 | I25: =COUNTIFS('Cleaned Data'!$L$2:$L$1501,3,'Cleaned Data'!$B$2:$B$1501,1) -> 85 | J25: =IF(H25=0,0,I25/H25) -> 0.18599562
G26: 4 | H26: =COUNTIFS('Cleaned Data'!$L$2:$L$1501,4) -> 421 | I26: =COUNTIFS('Cleaned Data'!$L$2:$L$1501,4,'Cleaned Data'!$B$2:$B$1501,1) -> 47 | J26: =IF(H26=0,0,I26/H26) -> 0.11163895
G27: 5 | H27: =COUNTIFS('Cleaned Data'!$L$2:$L$1501,5) -> 260 | I27: =COUNTIFS('Cleaned Data'!$L$2:$L$1501,5,'Cleaned Data'!$B$2:$B$1501,1) -> 17 | J27: =IF(H27=0,0,I27/H27) -> 0.065384615
B29: 7. Churn Rate by Risk Segment | G29: 8. Churn Rate by Tenure Bucket
B30: RiskSegment | C30: Customers | D30: Churned | E30: Churn Rate | G30: TenureBucket | H30: Customers | I30: Churned | J30: Churn Rate
B31: High Risk | C31: =COUNTIFS('Cleaned Data'!$W$2:$W$1501,"High Risk") -> 90 | D31: =COUNTIFS('Cleaned Data'!$W$2:$W$1501,"High Risk",'Cleaned Data'!$B$2:$B$1501,1) -> 20 | E31: =IF(C31=0,0,D31/C31) -> 0.22222222 | G31: 0-6 months | H31: =COUNTIFS('Cleaned Data'!$V$2:$V$1501,"0-6 months") -> 741 | I31: =COUNTIFS('Cleaned Data'!$V$2:$V$1501,"0-6 months",'Cleaned Data'!$B$2:$B$1501,1) -> 133 | J31: =IF(H31=0,0,I31/H31) -> 0.17948718
B32: Medium Risk | C32: =COUNTIFS('Cleaned Data'!$W$2:$W$1501,"Medium Risk") -> 486 | D32: =COUNTIFS('Cleaned Data'!$W$2:$W$1501,"Medium Risk",'Cleaned Data'!$B$2:$B$1501,1) -> 89 | E32: =IF(C32=0,0,D32/C32) -> 0.18312757 | G32: 7-12 months | H32: =COUNTIFS('Cleaned Data'!$V$2:$V$1501,"7-12 months") -> 349 | I32: =COUNTIFS('Cleaned Data'!$V$2:$V$1501,"7-12 months",'Cleaned Data'!$B$2:$B$1501,1) -> 52 | J32: =IF(H32=0,0,I32/H32) -> 0.14899713
B33: Low Risk | C33: =COUNTIFS('Cleaned Data'!$W$2:$W$1501,"Low Risk") -> 924 | D33: =COUNTIFS('Cleaned Data'!$W$2:$W$1501,"Low Risk",'Cleaned Data'!$B$2:$B$1501,1) -> 106 | E33: =IF(C33=0,0,D33/C33) -> 0.11471861 | G33: 13-24 months | H33: =COUNTIFS('Cleaned Data'!$V$2:$V$1501,"13-24 months") -> 288 | I33: =COUNTIFS('Cleaned Data'!$V$2:$V$1501,"13-24 months",'Cleaned Data'!$B$2:$B$1501,1) -> 24 | J33: =IF(H33=0,0,I33/H33) -> 0.083333333
G34: 25+ months | H34: =COUNTIFS('Cleaned Data'!$V$2:$V$1501,"25+ months") -> 122 | I34: =COUNTIFS('Cleaned Data'!$V$2:$V$1501,"25+ months",'Cleaned Data'!$B$2:$B$1501,1) -> 6 | J34: =IF(H34=0,0,I34/H34) -> 0.049180328
B37: 9. Churn Rate by Complaint Filed | G37: 10. Behavioural Averages: Churned vs Retained
B38: Complain | C38: Customers | D38: Churned | E38: Churn Rate | G38: Metric | H38: Retained (No) | I38: Churned (Yes)
B39: Complaint Filed | C39: =COUNTIFS('Cleaned Data'!$O$2:$O$1501,1) -> 429 | D39: =COUNTIFS('Cleaned Data'!$O$2:$O$1501,1,'Cleaned Data'!$B$2:$B$1501,1) -> 81 | E39: =IF(C39=0,0,D39/C39) -> 0.18881119 | G39: Avg Tenure (months) | H39: =ROUND(AVERAGEIFS('Cleaned Data'!$C$2:$C$1501,'Cleaned Data'!$X$2:$X$1501,"No"),2) -> 10.07 | I39: =ROUND(AVERAGEIFS('Cleaned Data'!$C$2:$C$1501,'Cleaned Data'!$X$2:$X$1501,"Yes"),2) -> 6.56
B40: No Complaint | C40: =COUNTIFS('Cleaned Data'!$O$2:$O$1501,0) -> 1071 | D40: =COUNTIFS('Cleaned Data'!$O$2:$O$1501,0,'Cleaned Data'!$B$2:$B$1501,1) -> 134 | E40: =IF(C40=0,0,D40/C40) -> 0.12511671 | G40: Avg Satisfaction Score | H40: =ROUND(AVERAGEIFS('Cleaned Data'!$L$2:$L$1501,'Cleaned Data'!$X$2:$X$1501,"No"),2) -> 3.33 | I40: =ROUND(AVERAGEIFS('Cleaned Data'!$L$2:$L$1501,'Cleaned Data'!$X$2:$X$1501,"Yes"),2) -> 2.94
G41: Avg Day Since Last Order | H41: =ROUND(AVERAGEIFS('Cleaned Data'!$S$2:$S$1501,'Cleaned Data'!$X$2:$X$1501,"No"),2) -> 4.23 | I41: =ROUND(AVERAGEIFS('Cleaned Data'!$S$2:$S$1501,'Cleaned Data'!$X$2:$X$1501,"Yes"),2) -> 5.21
G42: Avg Cashback Amount | H42: =ROUND(AVERAGEIFS('Cleaned Data'!$T$2:$T$1501,'Cleaned Data'!$X$2:$X$1501,"No"),2) -> 178.34 | I42: =ROUND(AVERAGEIFS('Cleaned Data'!$T$2:$T$1501,'Cleaned Data'!$X$2:$X$1501,"Yes"),2) -> 173.16
G43: Avg Order Count | H43: =ROUND(AVERAGEIFS('Cleaned Data'!$R$2:$R$1501,'Cleaned Data'!$X$2:$X$1501,"No"),2) -> 3.95 | I43: =ROUND(AVERAGEIFS('Cleaned Data'!$R$2:$R$1501,'Cleaned Data'!$X$2:$X$1501,"Yes"),2) -> 4.15
G44: Avg Coupon Used | H44: =ROUND(AVERAGEIFS('Cleaned Data'!$Q$2:$Q$1501,'Cleaned Data'!$X$2:$X$1501,"No"),2) -> 1.81 | I44: =ROUND(AVERAGEIFS('Cleaned Data'!$Q$2:$Q$1501,'Cleaned Data'!$X$2:$X$1501,"Yes"),2) -> 1.73

Sheet Dashboard
B2: Customer Churn Analysis — Dashboard
B3: E-Commerce Customer Churn | Simulated Dataset (1,500 customers) | All figures are live formulas
B5: Total Customers | F5: Churned Customers | J5: Overall Churn Rate | N5: High-Risk Customers | R5: Avg Satisfaction Score | V5: Customers with Complaints
B6: =COUNTA('Cleaned Data'!$A$2:$A$1501) -> 1500 | F6: =SUM('Cleaned Data'!$B$2:$B$1501) -> 215 | J6: =AVERAGE('Cleaned Data'!$B$2:$B$1501) -> 0.14333333 | N6: =COUNTIF('Cleaned Data'!$W$2:$W$1501,"High Risk") -> 90 | R6: =ROUND(AVERAGE('Cleaned Data'!$L$2:$L$1501),2) -> 3.28 | V6: =SUM('Cleaned Data'!$O$2:$O$1501) -> 429
